<mujoco model="Humanoid">
    <!--  Copyright © 2018, Roboti LLC

          This file is licensed under the MuJoCo Resource License (the "License").
          You may not use this file except in compliance with the License.
          You may obtain a copy of the License at

            https://www.roboti.us/resourcelicense.txt
    -->
    <compiler angle="radian" />
    <option timestep="0.005" tolerance="1e-10" jacobian="dense" iterations="50" />
    <size njmax="200" nconmax="50" nstack="10000" />
    <visual>
        <global offwidth="800" offheight="800" />
        <quality shadowsize="2048" />
        <map force="0.1" zfar="30" />
        <rgba haze="0.15 0.25 0.35 1" />
    </visual>
    <default class="main">
        <joint limited="true" damping="1" />
        <geom condim="1" material="matgeom" />
        <general ctrllimited="true" ctrlrange="-0.4 0.4" />
    </default>
    <asset>
        <texture type="skybox" builtin="gradient" rgb1="0.3 0.5 0.7" rgb2="0 0 0" width="512" height="3072" />
        <texture type="2d" name="texplane" builtin="checker" mark="cross" rgb1="0.2 0.3 0.4" rgb2="0.1 0.15 0.2" markrgb="0.8 0.8 0.8" width="512" height="512" />
        <texture type="cube" name="texgeom" builtin="flat" mark="cross" rgb1="0.8 0.6 0.4" rgb2="0.8 0.6 0.4" markrgb="1 1 1" width="127" height="762" />
        <material name="matplane" texture="texplane" texuniform="true" reflectance="0.3" />
        <material name="matgeom" texture="texgeom" texuniform="true" rgba="0.8 0.6 0.4 1" />
    </asset>
    <worldbody>
        <geom name="floor" size="0 0 0.25" type="plane" condim="3" material="matplane" />
        <light pos="0 0 5" dir="0 0 -1" castshadow="false" diffuse="0.2 0.2 0.2" specular="0 0 0" />
        <light target="torso" pos="0 0 4" dir="0 0 -1" diffuse="0.8 0.8 0.8" mode="targetbodycom" />
        <body name="torso" pos="0 0 1.4">
            <inertial pos="-0.00244621 0 0.0403624" quat="0.999916 0 0.0129592 0" mass="8.32208" diaginertia="0.15914 0.147625 0.0331318" />
            <joint name="root" type="free" limited="false" damping="0" />
            <geom name="torso1" size="0.07 0.07" quat="0.707107 0.707107 0 0" type="capsule" />
            <geom name="head" size="0.09" pos="0 0 0.19" />
            <geom name="uwaist" size="0.06 0.06" pos="-0.01 0 -0.12" quat="0.707107 0.707107 0 0" type="capsule" />
            <body name="lwaist" pos="-0.01 0 -0.26" quat="0.999998 0 -0.002 0">
                <inertial pos="0 0 0" quat="0.707107 0.707107 0 0" mass="2.03575" diaginertia="0.00732871 0.00732871 0.00366435" />
                <joint name="abdomen_z" pos="0 0 0.065" axis="0 0 1" stiffness="20" range="-0.785398 0.785398" armature="0.02" damping="5" />
                <joint name="abdomen_y" pos="0 0 0.065" axis="0 1 0" stiffness="10" range="-1.309 0.523599" armature="0.02" damping="5" />
                <geom name="lwaist" size="0.06 0.06" quat="0.707107 0.707107 0 0" type="capsule" />
                <body name="pelvis" pos="0 0 -0.165" quat="0.999998 0 -0.002 0">
                    <inertial pos="-0.02 0 0" quat="0.707107 0.707107 0 0" mass="5.85279" diaginertia="0.0376529 0.0376529 0.0237038" />
                    <joint name="abdomen_x" pos="0 0 0.1" axis="1 0 0" stiffness="10" range="-0.610865 0.610865" armature="0.02" damping="5" />
                    <geom name="butt" size="0.09 0.07" pos="-0.02 0 0" quat="0.707107 0.707107 0 0" type="capsule" />
                    <body name="right_thigh" pos="0 -0.1 -0.04">
                        <inertial pos="0 0.005 -0.17" quat="0.999892 0.0147011 0 0" mass="4.52556" diaginertia="0.0644581 0.0644581 0.008146" />
                        <joint name="right_hip_x" pos="0 0 0" axis="1 0 0" stiffness="10" range="-0.436332 0.0872665" armature="0.01" damping="5" />
                        <joint name="right_hip_z" pos="0 0 0" axis="0 0 1" stiffness="10" range="-1.0472 0.610865" armature="0.01" damping="5" />
                        <joint name="right_hip_y" pos="0 0 0" axis="0 1 0" stiffness="20" range="-2.0944 0.349066" armature="0.01" damping="5" />
                        <geom name="right_thigh1" size="0.06 0.170074" pos="0 0.005 -0.17" quat="0.999892 0.0147011 0 0" type="capsule" />
                        <body name="right_shin" pos="0 0.01 -0.403">
                            <inertial pos="0 0 -0.15" mass="2.63249" diaginertia="0.0283002 0.0283002 0.00316031" />
                            <joint name="right_knee" pos="0 0 0.02" axis="0 -1 0" stiffness="1" range="-2.79253 -0.0349066" armature="0.006" />
                            <geom name="right_shin1" size="0.049 0.15" pos="0 0 -0.15" type="capsule" />
                            <body name="right_foot" pos="0 0 -0.39">
                                <inertial pos="0.035 -0.01 0" quat="0 0.707107 0 0.707107" mass="1.08992" diaginertia="0.00577723 0.00529682 0.000877682" />
                                <joint name="right_ankle_y" pos="0 0 0.08" axis="0 1 0" stiffness="4" range="-0.872665 0.872665" armature="0.0008" />
                                <joint name="right_ankle_x" pos="0 0 0.04" axis="0.894427 0 0.447214" stiffness="1" range="-0.872665 0.872665" armature="0.0006" />
                                <geom name="right_foot_cap1" size="0.027 0.105475" pos="0.035 -0.03 0" quat="0.707107 -0.0670402 -0.703922 0" type="capsule" />
                                <geom name="right_foot_cap2" size="0.027 0.105475" pos="0.035 0.01 0" quat="0.707107 0.0670402 -0.703922 0" type="capsule" />
                            </body>
                        </body>
                    </body>
                    <body name="left_thigh" pos="0 0.1 -0.04">
                        <inertial pos="0 -0.005 -0.17" quat="0.999892 -0.0147011 0 0" mass="4.52556" diaginertia="0.0644581 0.0644581 0.008146" />
                        <joint name="left_hip_x" pos="0 0 0" axis="-1 0 0" stiffness="10" range="-0.436332 0.0872665" armature="0.01" damping="5" />
                        <joint name="left_hip_z" pos="0 0 0" axis="0 0 -1" stiffness="10" range="-1.0472 0.610865" armature="0.01" damping="5" />
                        <joint name="left_hip_y" pos="0 0 0" axis="0 1 0" stiffness="20" range="-2.0944 0.349066" armature="0.01" damping="5" />
                        <geom name="left_thigh1" size="0.06 0.170074" pos="0 -0.005 -0.17" quat="0.999892 -0.0147011 0 0" type="capsule" />
                        <body name="left_shin" pos="0 -0.01 -0.403">
                            <inertial pos="0 0 -0.15" mass="2.63249" diaginertia="0.0283002 0.0283002 0.00316031" />
                            <joint name="left_knee" pos="0 0 0.02" axis="0 -1 0" stiffness="1" range="-2.79253 -0.0349066" armature="0.006" />
                            <geom name="left_shin1" size="0.049 0.15" pos="0 0 -0.15" type="capsule" />
                            <body name="left_foot" pos="0 0 -0.39">
                                <inertial pos="0.035 0.01 0" quat="0 0.707107 0 0.707107" mass="1.08992" diaginertia="0.00577723 0.00529682 0.000877682" />
                                <joint name="left_ankle_y" pos="0 0 0.08" axis="0 1 0" stiffness="4" range="-0.872665 0.872665" armature="0.0008" />
                                <joint name="left_ankle_x" pos="0 0 0.04" axis="0.894427 0 0.447214" stiffness="1" range="-0.872665 0.872665" armature="0.0006" />
                                <geom name="left_foot_cap1" size="0.027 0.105475" pos="0.035 0.03 0" quat="0.707107 0.0670402 -0.703922 0" type="capsule" />
                                <geom name="left_foot_cap2" size="0.027 0.105475" pos="0.035 -0.01 0" quat="0.707107 -0.0670402 -0.703922 0" type="capsule" />
                            </body>
                        </body>
                    </body>
                </body>
            </body>
            <body name="right_upper_arm" pos="0 -0.17 0.06">
                <inertial pos="0.08 -0.08 -0.08" quat="0.888074 -0.325058 -0.325058 0" mass="1.59406" diaginertia="0.0139972 0.0139972 0.00127525" />
                <joint name="right_shoulder1" pos="0 0 0" axis="0.816497 0.408248 0.408248" stiffness="1" range="-1.48353 1.0472" armature="0.0068" />
                <joint name="right_shoulder2" pos="0 0 0" axis="0 -0.707107 0.707107" stiffness="1" range="-1.48353 1.0472" armature="0.0051" />
                <geom name="right_uarm1" size="0.04 0.138564" pos="0.08 -0.08 -0.08" quat="0.888074 -0.325058 -0.325058 0" type="capsule" />
                <body name="right_lower_arm" pos="0.18 -0.18 -0.18">
                    <inertial pos="0.110134 0.110134 0.110134" quat="0.424708 0.820473 -0.339851 -0.17592" mass="1.19834" diaginertia="0.0128123 0.0128123 0.000618563" />
                    <joint name="right_elbow" pos="0 0 0" axis="0 -0.707107 0.707107" range="-1.5708 0.872665" armature="0.0028" />
                    <geom name="right_larm" size="0.031 0.138564" pos="0.09 0.09 0.09" quat="0.459701 0.627963 -0.627963 0" type="capsule" />
                    <geom name="right_hand" size="0.04" pos="0.18 0.18 0.18" />
                </body>
            </body>
            <body name="left_upper_arm" pos="0 0.17 0.06">
                <inertial pos="0.08 0.08 -0.08" quat="0.888074 0.325058 -0.325058 0" mass="1.59406" diaginertia="0.0139972 0.0139972 0.00127525" />
                <joint name="left_shoulder1" pos="0 0 0" axis="0.816497 -0.408248 0.408248" stiffness="1" range="-1.0472 1.48353" armature="0.0068" />
                <joint name="left_shoulder2" pos="0 0 0" axis="0 0.707107 0.707107" stiffness="1" range="-1.0472 1.48353" armature="0.0051" />
                <geom name="left_uarm1" size="0.04 0.138564" pos="0.08 0.08 -0.08" quat="0.888074 0.325058 -0.325058 0" type="capsule" />
                <body name="left_lower_arm" pos="0.18 0.18 -0.18">
                    <inertial pos="0.110134 -0.110134 0.110134" quat="0.820473 0.424708 0.17592 0.339851" mass="1.19834" diaginertia="0.0128123 0.0128123 0.000618563" />
                    <joint name="left_elbow" pos="0 0 0" axis="0 -0.707107 -0.707107" range="-1.5708 0.872665" armature="0.0028" />
                    <geom name="left_larm" size="0.031 0.138564" pos="0.09 -0.09 0.09" quat="0.459701 -0.627963 -0.627963 0" type="capsule" />
                    <geom name="left_hand" size="0.04" pos="0.18 -0.18 0.18" />
                </body>
            </body>
        </body>
    </worldbody>
    <actuator>
        <general name="abdomen_y" joint="abdomen_y" gear="200 0 0 0 0 0" />
        <general name="abdomen_z" joint="abdomen_z" gear="200 0 0 0 0 0" />
        <general name="abdomen_x" joint="abdomen_x" gear="200 0 0 0 0 0" />
        <general name="right_hip_x" joint="right_hip_x" gear="200 0 0 0 0 0" />
        <general name="right_hip_z" joint="right_hip_z" gear="200 0 0 0 0 0" />
        <general name="right_hip_y" joint="right_hip_y" gear="600 0 0 0 0 0" />
        <general name="right_knee" joint="right_knee" gear="400 0 0 0 0 0" />
        <general name="right_ankle_x" joint="right_ankle_x" gear="100 0 0 0 0 0" />
        <general name="right_ankle_y" joint="right_ankle_y" gear="100 0 0 0 0 0" />
        <general name="left_hip_x" joint="left_hip_x" gear="200 0 0 0 0 0" />
        <general name="left_hip_z" joint="left_hip_z" gear="200 0 0 0 0 0" />
        <general name="left_hip_y" joint="left_hip_y" gear="600 0 0 0 0 0" />
        <general name="left_knee" joint="left_knee" gear="400 0 0 0 0 0" />
        <general name="left_ankle_x" joint="left_ankle_x" gear="100 0 0 0 0 0" />
        <general name="left_ankle_y" joint="left_ankle_y" gear="100 0 0 0 0 0" />
        <general name="right_shoulder1" joint="right_shoulder1" gear="100 0 0 0 0 0" />
        <general name="right_shoulder2" joint="right_shoulder2" gear="100 0 0 0 0 0" />
        <general name="right_elbow" joint="right_elbow" gear="200 0 0 0 0 0" />
        <general name="left_shoulder1" joint="left_shoulder1" gear="100 0 0 0 0 0" />
        <general name="left_shoulder2" joint="left_shoulder2" gear="100 0 0 0 0 0" />
        <general name="left_elbow" joint="left_elbow" gear="200 0 0 0 0 0" />
    </actuator>
</mujoco>
